Workbook

Sheet Valeurs
A1: LIBERE
A2: NON LIBERE
A3: NON CONFORME

Sheet MASSE
C1: Situation Stock Masse
C3: LIBERES | E3: =SUMIF(U9:U890,"LIBERE",S9:S94) -> 3023000 | K3: NON LIBERES | M3: =SUMIF(U9:U1048576,"NON LIBERE",S9:S57) -> 180000 | Q3: VENDUS NON EMPOTÉS | U3: =SUM(G11:G13) -> 0 | W3: REFONTE | X3: =SUM(AB9:AB45) -> 13421 | Y3: DECHETS PRODUCTION MASSE & TOURTEAUX A VENDRE LOCALEMENT | Z3: =SUM(AB65+AB66+AB67) -> 0 | AA3: NC A VENDRE (export) | AB3: =SUMIF(X9:X1048576,"NC-A VENDRE",Z9:Z1048576) -> 197000 | AC3: DECHETS PRODUCTION MASSE & BEURRE A REFONDRE | AD3: =SUM(AB68+AB69) -> 31573
G4: =COUNTIF(U9:U1048576,Valeurs!A1)&" lots" -> 156 lots | O4: =COUNTIF(U9:U1048576,Valeurs!A2)&" lots" -> 9 lots | U4: =COUNT(G11:G13)&" lots" -> 0 lots | W4: LOTS A REFONDRE | AA4: NC A VENDRE
W5: Date Production | Y5: Numero de lot | Z5: Poids initial | AA5: Poids réfondus | AB5: Poids restant
AA6: Suivi réfonte | AC6: POIDS BRUT
B7: LES LOTS DE MASSE DE CACAO VENDUS NON EMBARQUES | N7: LES LOTS DE MASSE DE CACAO EN STOCK
A8: DATE | B8: NBRE-LOT | C8: N° LOT PRODUIT | D8: NATURE | E8: NOMBRE PALETTE | F8: NOMBRE CARTON | G8: POIDS NET | H8: POIDS BRUT | I8: STATUT | J8: OT | K8: CLIENT | M8: DATE | N8: NBRE-LOT | O8: N° LOT PRODUIT | P8: NATURE | Q8: NOMBRE PALETTE | R8: NOMBRE CARTON | S8: POIDS NET | T8: POIDS BRUT | U8: STATUT
M9: 45723 | N9: 1 | O9: 2502112301 | P9: Masse de Cacao | Q9: 4 | R9: 160 | S9: 4000 | T9: 4146 | U9: LIBERE | X9: NC-VENDU | Y9: 2312112301 | Z9: 1000 | AA9: 1000 | AB9: 0
M10: 45761 | N10: 1 | O10: 2510412301 | P10: Masse de Cacao | Q10: 20 | R10: 800 | S10: 20000 | T10: 20792 | U10: LIBERE | W10: 45507 | X10: REFONTE | Y10: DIVERS | Z10: 6000 | AB10: =Z10-AA10 -> 6000
M11: 45765 | N11: 1 | O11: 2510712301 | P11: Masse de Cacao | Q11: 1 | R11: 40 | S11: 1000 | T11: 1031 | U11: LIBERE | W11: 45520 | X11: NC-VENDU | Y11: 2422012301 | Z11: 20000 | AA11: 20000 | AB11: =Z11-AA11 -> 0
M12: 45779 | N12: 1 | O12: 2512012302 | P12: Masse de Cacao | Q12: 14 | R12: 560 | S12: 14000 | T12: 14582 | U12: LIBERE | X12: REFONTE | Y12: CARTON ENDO | Z12: 9615 | AA12: 6119 | AB12: =Z12-AA12 -> 3496
M13: 45790 | N13: 1 | O13: 2513212301 | P13: Masse de Cacao | Q13: 16 | R13: 640 | S13: 16000 | T13: 16671 | U13: LIBERE | W13: 45490 | X13: NC-VENDU | Y13: 2418512301 | Z13: 9000 | AA13: 9000 | AB13: =Z13-AA13 -> 0
M14: 45798 | N14: 1 | O14: 2514112301 | P14: Masse de Cacao | Q14: 20 | R14: 800 | S14: 20000 | T14: 20838 | U14: LIBERE | W14: 45491 | X14: NC-VENDU | Y14: 2419312301 | Z14: 2000 | AA14: 2000 | AB14: =Z14-AA14 -> 0
M15: 45800 | N15: 1 | O15: 2514312301 | P15: Masse de Cacao | Q15: 20 | R15: 800 | S15: 20000 | T15: 20820 | U15: LIBERE | W15: 45491 | X15: NC-VENDU | Y15: 2419112302 | Z15: 2000 | AA15: 2000 | AB15: =Z15-AA15 -> 0
M16: 45803 | N16: 1 | O16: 2514512301 | P16: Masse de Cacao | Q16: 20 | R16: 800 | S16: 20000 | T16: 20825 | U16: LIBERE | W16: 45495 | X16: REFONTE | Y16: 2419412302 | Z16: 925 | AB16: 925 | AC16: 960
M17: 45803 | N17: 1 | O17: 2514612301 | P17: Masse de Cacao | Q17: 20 | R17: 800 | S17: 20000 | T17: 20834 | U17: LIBERE | W17: 45469 | X17: NC-VENDU | Y17: 2417012301 | Z17: 5000 | AA17: 5000 | AB17: =Z17-AA17 -> 0
M18: 45804 | N18: 1 | O18: 2514612302 | P18: Masse de Cacao | Q18: 20 | R18: 800 | S18: 20000 | T18: 20870 | U18: LIBERE | W18: 45495 | X18: NC-A VENDRE | Y18: 2419612301 | Z18: 2000 | AB18: =Z18-AA18 -> 2000 | AC18: 2050
M19: 45805 | N19: 1 | O19: 2514712301 | P19: Masse de Cacao | Q19: 20 | R19: 800 | S19: 20000 | T19: 20883 | U19: LIBERE | W19: 45502 | X19: NC-VENDU | Y19: 2419712302 | Z19: 20000 | AA19: 20000 | AB19: =Z19-AA19 -> 0
M20: 45808 | N20: 1 | O20: 2514912301 | P20: Masse de Cacao | Q20: 20 | R20: 800 | S20: 20000 | T20: 20897 | U20: LIBERE | W20: 45520 | X20: NC-VENDU | Y20: 2421712301 | Z20: 4000 | AA20: 4000 | AB20: =Z20-AA20 -> 0
M21: 45808 | N21: 1 | O21: 2515112301 | P21: Masse de Cacao | Q21: 20 | R21: 800 | S21: 20000 | T21: 20909 | U21: LIBERE | W21: 45503 | X21: NC-VENDU | Y21: 2420412301 | Z21: 2000 | AA21: 2000 | AB21: =Z21-AA21 -> 0
M22: 45809 | N22: 1 | O22: 2515112302 | P22: Masse de Cacao | Q22: 20 | R22: 800 | S22: 20000 | T22: 20882 | U22: LIBERE | W22: 45490 | X22: NC-VENDU | Y22: 2418112301 | Z22: 12000 | AA22: 12000 | AB22: =Z22-AA22 -> 0
M23: 45814 | N23: 1 | O23: 2515512301 | P23: Masse de Cacao | Q23: 20 | R23: 800 | S23: 20000 | T23: 20861 | U23: LIBERE | W23: 45530 | X23: NC-VENDU | Y23: 2422312302 | Z23: 20000 | AA23: 20000 | AB23: =Z23-AA23 -> 0
M24: 45817 | N24: 1 | O24: 2516012301 | P24: Masse de Cacao | Q24: 20 | R24: 800 | S24: 20000 | T24: 20877 | U24: LIBERE | W24: 45495 | X24: NC-VENDU | Y24: 2419712301 | Z24: 7000 | AA24: 7000 | AB24: =Z24-AA24 -> 0
M25: 45822 | N25: 1 | O25: 2516112301 | P25: Masse de Cacao | Q25: 20 | R25: 800 | S25: 20000 | T25: 20885 | U25: LIBERE | W25: 45503 | X25: NC-VENDU | Y25: 2420312301 | Z25: 1000 | AA25: 1000 | AB25: =Z25-AA25 -> 0
M26: 45825 | N26: 1 | O26: 2516712301 | P26: Masse de Cacao | Q26: 20 | R26: 800 | S26: 20000 | T26: 20796 | U26: LIBERE | W26: 45505 | X26: NC-VENDU | Y26: 2420612301 | Z26: 3000 | AA26: 3000 | AB26: 0
B27: =SUM(B11:B13) -> 0 | E27: =SUM(E11:E13) -> 0 | F27: =SUM(F11:F13) -> 0 | G27: =SUM(G11:G13) -> 0 | M27: 45827 | N27: 1 | O27: 2516812302 | P27: Masse de Cacao | Q27: 20 | R27: 800 | S27: 20000 | T27: 20804 | U27: LIBERE | W27: 45530 | X27: NC-VENDU | Y27: 2422412301 | Z27: 2000 | AA27: 2000 | AB27: =Z27-AA27 -> 0
M28: 45830 | N28: 1 | O28: 2517012301 | P28: Masse de Cacao | Q28: 20 | R28: 800 | S28: 20000 | T28: 20842 | U28: LIBERE | W28: 45510 | X28: NC-VENDU | Y28: 2419212301 | Z28: 2000 | AA28: 2000 | AB28: =Z28-AA28 -> 0
M29: 45831 | N29: 1 | O29: 2517312301 | P29: Masse de Cacao | Q29: 20 | R29: 800 | S29: 20000 | T29: 20773 | U29: LIBERE | W29: 45520 | X29: NC-VENDU | Y29: 2422312301 | Z29: 20000 | AA29: 20000 | AB29: =Z29-AA29 -> 0
M30: 45834 | N30: 1 | O30: 2517712301 | P30: Masse de Cacao | Q30: 20 | R30: 800 | S30: 20000 | T30: 20837 | U30: LIBERE | W30: 45520 | X30: NC-VENDU | Y30: 2422112301 | Z30: 20000 | AA30: 20000 | AB30: =Z30-AA30 -> 0
M31: 45836 | N31: 1 | O31: 2517912301 | P31: Masse de Cacao | Q31: 20 | R31: 800 | S31: 20000 | T31: 20837 | U31: LIBERE | W31: 45323 | X31: REFONTE | Y31: 2336412302 | Z31: 1000 | AB31: =Z31-AA31 -> 1000
M32: 45845 | N32: 1 | O32: 2518712301 | P32: Masse de Cacao | Q32: 20 | R32: 800 | S32: 20000 | T32: 20859 | U32: LIBERE | W32: 45520 | X32: NC-VENDU | Y32: 2422012302 | Z32: 20000 | AA32: 20000 | AB32: =Z32-AA32 -> 0
M33: 45848 | N33: 1 | O33: 2519012301 | P33: Masse de Cacao | Q33: 20 | R33: 800 | S33: 20000 | T33: 20833 | U33: LIBERE | W33: 45560 | X33: NC-VENDU | Y33: 2423812301 | Z33: 7000 | AA33: 7000 | AB33: =Z33-AA33 -> 0
M34: 45850 | N34: 1 | O34: 2519212301 | P34: Masse de Cacao | Q34: 20 | R34: 800 | S34: 20000 | T34: 20840 | U34: LIBERE | W34: 45560 | X34: NC-VENDU | Y34: 2424012301 | Z34: 6000 | AA34: 6000 | AB34: =Z34-AA34 -> 0
M35: 45855 | N35: 1 | O35: 2519612301 | P35: Masse de Cacao | Q35: 20 | R35: 800 | S35: 20000 | T35: 20850 | U35: LIBERE | W35: 45573 | X35: NC-VENDU | Y35: 2427212301 | Z35: 2000 | AA35: 2000 | AB35: =Z35-AA35 -> 0
M36: 45856 | N36: 1 | O36: 2519812301 | P36: Masse de Cacao | Q36: 20 | R36: 800 | S36: 20000 | T36: 20871 | U36: LIBERE | W36: 45573 | X36: NC-VENDU | Y36: 2427312301 | Z36: 3000 | AA36: 3000 | AB36: =Z36-AA36 -> 0
M37: 45859 | N37: 1 | O37: 2520212301 | P37: Masse de Cacao | Q37: 20 | R37: 800 | S37: 20000 | T37: 20802 | U37: LIBERE | W37: 45575 | X37: NC-VENDU | Y37: 2427212302 | Z37: 4000 | AA37: 4000 | AB37: =Z37-AA37 -> 0
M38: 45864 | N38: 1 | O38: 2520312302 | P38: Masse de Cacao | Q38: 20 | R38: 800 | S38: 20000 | T38: 20880 | U38: LIBERE | W38: 45588 | X38: NC-VENDU | Y38: 2425512301 | Z38: 4000 | AA38: 4000 | AB38: =Z38-AA38 -> 0 | AC38: 4201
M39: 45865 | N39: 1 | O39: 2520712301 | P39: Masse de Cacao | Q39: 20 | R39: 800 | S39: 20000 | T39: 20867 | U39: LIBERE | W39: 45588 | X39: NC-VENDU | Y39: 2425612301 | Z39: 9000 | AA39: 9000 | AB39: =Z39-AA39 -> 0 | AC39: 9393
M40: 45871 | N40: 1 | O40: 2521312301 | P40: Masse de Cacao | Q40: 20 | R40: 800 | S40: 20000 | T40: 20838 | U40: LIBERE | W40: 45608 | X40: NC-VENDU | Y40: 2430812301 | Z40: 10000 | AA40: 10000 | AB40: =Z40-AA40 -> 0 | AC40: 10395
M41: 45874 | N41: 1 | O41: 2521412301 | P41: Masse de Cacao | Q41: 20 | R41: 800 | S41: 20000 | T41: 20926 | U41: LIBERE | W41: 45615 | X41: NC-VENDU | Y41: 2431012301 | Z41: 5000 | AA41: 5000 | AB41: =Z41-AA41 -> 0 | AC41: 5202
...

Sheet TOURTEAU
C1: Situation Stock TOURTEAU
C3: LIBERES | E3: =SUMIF(S16:S1048539,"LIBERE",Q16:Q454) -> 529000 | J3: NON LIBERES | L3: =SUMIF(S16:S1048539,"NON LIBERE",Q16:Q454) -> 34000 | P3: VENDUS NON EMPOTÉS | S3: =SUM(F9:F43) -> 0 | U3: NON CONFORME | X3: =SUMIF(S9:S1048539,"NON CONFORME",Q9:Q454) -> 29000
F4: =COUNTIF(S16:S1048539,Valeurs!A1)&" Big Bag" -> 529 Big Bag | N4: =COUNTIF(S16:S1048539,Valeurs!A2)&" Big Bag" -> 34 Big Bag | S4: =COUNT(F9:F43)&" lots" -> 0 lots | X4: =COUNTIF(S16:S1048539,Valeurs!A3)&" Big Bag" -> 22 Big Bag
B7: LES LOTS DE TOURTEAU DE CACAO VENDUS NON EMBARQUES | M7: LES LOTS DE TOURTEAU DE CACAO EN STOCK
A8: DATE | B8: NBRE LOTS | C8: N° LOT PRODUIT | D8: NATURE | E8: NOMBRE PALETTE | F8: POIDS NET | G8: POIDS BRUT | H8: STATUT | I8: OT | J8: CLIENT | L8: DATE | M8: NBRE BB | N8: NUMERO BB | O8: N° LOT PRODUIT | P8: NATURE | Q8: POIDS NET | R8: POIDS BRUT | S8: STATUT
L9: 45441 | M9: 1 | N9: 12 | O9: 2429913501 | P9: TOURTEAUX | Q9: 1000 | S9: NON CONFORME
L10: 45442 | M10: 1 | N10: 13 | O10: 2429913501 | P10: TOURTEAUX | Q10: 1000 | S10: NON CONFORME
L11: 45442 | M11: 1 | N11: 15 | O11: 2429913501 | P11: TOURTEAUX | Q11: 1000 | S11: NON CONFORME
L12: 45442 | M12: 1 | N12: 16 | O12: 2429913501 | P12: TOURTEAUX | Q12: 1000 | S12: NON CONFORME
L13: 45442 | M13: 1 | N13: 18 | O13: 2429913501 | P13: TOURTEAUX | Q13: 1000 | S13: NON CONFORME
L14: 45444 | M14: 1 | N14: 19 | O14: 2429913501 | P14: TOURTEAUX | Q14: 1000 | S14: NON CONFORME
L15: 45444 | M15: 1 | N15: 20 | O15: 2429913501 | P15: TOURTEAUX | Q15: 1000 | S15: NON CONFORME
L16: 45927 | M16: 1 | N16: 20 | O16: 2526713501 | P16: TOURTEAU | Q16: 1000 | R16: 1013 | S16: LIBERE
L17: 45927 | M17: 1 | N17: 1 | O17: 2527013501 | P17: TOURTEAU | Q17: 1000 | R17: 1014 | S17: LIBERE
L18: 45927 | M18: 1 | N18: 2 | O18: 2527013501 | P18: TOURTEAU | Q18: 1000 | R18: 1015 | S18: LIBERE
L19: 45928 | M19: 1 | N19: 4 | O19: 2527013501 | P19: TOURTEAU | Q19: 1000 | R19: 1021 | S19: LIBERE
L20: 45928 | M20: 1 | N20: 5 | O20: 2527013501 | P20: TOURTEAUT | Q20: 1000 | R20: 1024 | S20: LIBERE
L21: 45928 | M21: 1 | N21: 6 | O21: 2527013501 | P21: TOURTEAU | Q21: 1000 | R21: 1014 | S21: LIBERE
L22: 45929 | M22: 1 | N22: 8 | O22: 2527013501 | P22: TOURTEAU | Q22: 1000 | R22: 1012 | S22: LIBERE
L23: 45929 | M23: 1 | N23: 9 | O23: 2527013501 | P23: TOURTEAU | Q23: 1000 | R23: 1016 | S23: LIBERE
L24: 45929 | M24: 1 | N24: 10 | O24: 2527013501 | P24: TOURTEAU | Q24: 1000 | R24: 1005 | S24: LIBERE
L25: 45929 | M25: 1 | N25: 11 | O25: 2527013501 | P25: TOURTEAU | Q25: 1000 | R25: 1017 | S25: LIBERE
L26: 45929 | M26: 1 | N26: 12 | O26: 2527013501 | P26: TOURTEAU | Q26: 1000 | R26: 1016 | S26: LIBERE
L27: 45929 | M27: 1 | N27: 13 | O27: 2527013501 | P27: TOURTEAU | Q27: 1000 | R27: 1015 | S27: LIBERE
... L44: 45933 | M44: 1 | N44: 11 | O44: 2527413501 | P44: TOURTEAU | Q44: 1000 | R44: 1013 | S44: LIBERE
B45: =SUM(B9:B43) -> 0 | E45: =SUM(E9:E43) -> 0 | F45: =SUM(F9:F43) -> 0 | G45: =SUM(E45:F45) -> 0 | L45: 45938 | M45: 1 | N45: 12 | O45: 2527413501 | P45: TOURTEAU | Q45: 1000 | R45: 1013 | S45: LIBERE
L46: 45938 | M46: 1 | N46: 13 | O46: 2527413501 | P46: TOURTEAU | Q46: 1000 | R46: 1013 | S46: LIBERE
L47: 45938 | M47: 1 | N47: 14 | O47: 2527413501 | P47: TOURTEAU | Q47: 1000 | R47: 1013 | S47: LIBERE
L48: 45938 | M48: 1 | N48: 15 | O48: 2527413501 | P48: TOURTEAU | Q48: 1000 | R48: 1013 | S48: LIBERE
L49: 45938 | M49: 1 | N49: 16 | O49: 2527413501 | P49: TOURTEAU | Q49: 1000 | R49: 1013 | S49: LIBERE
L50: 45938 | M50: 1 | N50: 17 | O50: 2527413501 | P50: TOURTEAU | Q50: 1000 | R50: 1013 | S50: LIBERE
L51: 45942 | M51: 1 | N51: 18 | O51: 2527413501 | P51: TOURTEAU | Q51: 1000 | R51: 1013 | S51: LIBERE
L52: 45942 | M52: 1 | N52: 19 | O52: 2527413501 | P52: TOURTEAU | Q52: 1000 | R52: 1013 | S52: LIBERE
L53: 45942 | M53: 1 | N53: 20 | O53: 2527413501 | P53: TOURTEAU | Q53: 1000 | R53: 1013 | S53: LIBERE
L54: 45942 | M54: 1 | N54: 1 | O54: 2528513501 | P54: TOURTEAU | Q54: 1000 | R54: 1015 | S54: LIBERE
L55: 45942 | M55: 1 | N55: 2 | O55: 2528513501 | P55: TOURTEAU | Q55: 1000 | R55: 1015 | S55: LIBERE
L56: 45942 | M56: 1 | N56: 3 | O56: 2528513501 | P56: TOURTEAU | Q56: 1000 | R56: 1017 | S56: LIBERE
L57: 45942 | M57: 1 | N57: 4 | O57: 2528513501 | P57: TOURTEAU | Q57: 1000 | R57: 1014 | S57: LIBERE
... L259: 45973 | M259: 1 | N259: 16 | O259: 2531413501 | P259: TOURTEAU | Q259: 1000 | R259: 1020 | S259: LIBERE
L260: 45973 | M260: 1 | N260: 17 | O260: 2531413501 | P260: TOURTEAU | Q260: 1000 | S260: LIBERE
...

Sheet BEURRE
C1: Situation Stock Beurre
C3: LIBERES | E3: =SUMIF(U9:U45,"LIBERE",S9:S45) -> 48000 | K3: NON LIBERES | M3: =SUMIF(U9:U1048576,"NON LIBERE",S9:S33) -> 0 | Q3: VENDUS NON EMPOTÉS | U3: =SUM(G14:G32) -> 0 | W3: REFONTE | X3: =SUMIF(X9:X1048576,"REFONTE",Z9:Z1048576) -> 0 | AA3: NC A VENDRE | AB3: =SUMIF(X9:X1048576,"NC-A VENDRE",Z9:Z1048576) -> 0
G4: =COUNTIF(U9:U1048576,Valeurs!A1)&" lots" -> 3 lots | O4: =COUNTIF(U9:U1048576,Valeurs!A2)&" lots" -> 0 lots | U4: =COUNT(G14:G32)&" lots" -> 0 lots | W4: LOTS A REFONDRE | AA4: NC A VENDRE
W5: Date Production | Y5: Numero de lot | Z5: Poids initial | AA5: Poids réfondus | AB5: Poids restant
B7: LES LOTS DE BEURRE DE CACAO VENDUS NON EMBARQUES | N7: LES LOTS DE BEURRE DE CACAO EN STOCK
A8: DATE | B8: NBRE-LOT | C8: N° LOT PRODUIT | D8: NATURE | E8: NOMBRE PALETTE | F8: NOMBRE CARTON | G8: POIDS NET | H8: POIDS BRUT | I8: STATUT | J8: OT | K8: CLIENT | M8: DATE | N8: NBRE-LOT | O8: N° LOT PRODUIT | P8: NATURE | Q8: NOMBRE PALETTE | R8: NOMBRE CARTON | S8: POIDS NET | T8: POIDS BRUT | U8: STATUT
M9: 45839 | N9: 1 | O9: 2518215401 | P9: Beurre de cacao | Q9: 8 | R9: 320 | S9: 8000 | T9: 8275 | U9: LIBERE
M10: 46137 | N10: 1 | O10: 2533315401 | P10: Beurre de cacao | Q10: 20 | R10: 800 | S10: 20000 | T10: 20801 | U10: LIBERE
M11: 46140 | N11: 1 | O11: 2611515401 | P11: Beurre de cacao | Q11: 20 | R11: 800 | S11: 20000 | U11: LIBERE
B33: =SUM(B14:B32) -> 0 | E33: =SUM(E14:E32) -> 0 | F33: =SUM(F14:F32) -> 0 | G33: =SUM(G14:G32) -> 0
N36: =SUM(N9:N35) -> 3 | Q36: =SUM(Q9:Q35) -> 48 | R36: =SUM(R9:R35) -> 1920 | S36: =SUM(S9:S35) -> 48000

Sheet GRAPHIQUES
C4: STOCk DISPO LIBERE | D4: STOCK DISPO EN ATTENTE LIBERATION | E4: STOCK DISPO N.C | F4: TOTAL CUMULE / PRODUIT
B5: MASSE | C5: =+MASSE!E3 -> 3023000 | D5: =+MASSE!M3 -> 180000 | E5: =+MASSE!AB3 -> 197000 | F5: =SUM(C5:E5) -> 3400000
B6: BEURRE | C6: =+BEURRE!E3 -> 48000 | D6: =+BEURRE!M3 -> 0 | E6: =+BEURRE!AB3 -> 0 | F6: =SUM(C6:E6) -> 48000
B7: TOURTEAU | C7: =+TOURTEAU!E3 -> 529000 | D7: =+TOURTEAU!L3 -> 34000 | E7: =+TOURTEAU!X3 -> 29000 | F7: =SUM(C7:E7) -> 592000

Sheet Contrôle TEST PESEE
B2: MASSE | K2: BEURRE | T2: TOURTEAU
B3: Nbre de Lot | C3: N° Lot | E3: Palettes Pesées | K3: Nbre de Lot | L3: N° Lot | N3: Palettes Pesées | T3: Nbre de Lot | U3: N° Lot | W3: Palettes Pesées
E5: N° Pal | F5: Poids Brut | G5: Tare Palette | H5: Tare Emballage | I5: Poids Net | N5: N° Pal | O5: Poids Brut | P5: Tare Palette | Q5: Tare Emballage | R5: Poids Net | W5: N° Pal | X5: Poids Brut | Y5: Tare Palette | Z5: Tare Emballage | AA5: Poids Net
B6: 1 | C6: 2600112301 | E6: P3 | F6: 1043 | G6: 19 | H6: 18 | I6: =+F6-SUM(G6:H6) -> 1006 | K6: 1 | L6: 2518215401 | N6: P1 | O6: 1040 | P6: 19 | Q6: 18 | R6: =+O6-SUM(P6:Q6) -> 1003 | T6: 1 | U6: 2522913501 | AA6: =+X6-SUM(Y6:Z6) -> 0
E7: P20 | F7: 1039 | G7: 19 | H7: 18 | I7: =+F7-SUM(G7:H7) -> 1002 | N7: P4 | O7: 1039 | P7: 19 | Q7: 18 | R7: =+O7-SUM(P7:Q7) -> 1002 | AA7: =+X7-SUM(Y7:Z7) -> 0
E8: P9 | F8: 1036 | G8: 19 | H8: 18 | I8: =+F8-SUM(G8:H8) -> 999 | N8: P18 | O8: 1041 | P8: 19 | Q8: 18 | R8: =+O8-SUM(P8:Q8) -> 1004 | AA8: =+X8-SUM(Y8:Z8) -> 0
B9: 1 | C9: 2600312301 | E9: P6 | F9: 1041 | G9: 19 | H9: 18 | I9: =+F9-SUM(G9:H9) -> 1004 | K9: 1 | L9: 2533315401 | N9: P7 | O9: 1032 | P9: 19 | Q9: 18 | R9: =+O9-SUM(P9:Q9) -> 995 | T9: 1 | U9: 2523313501 | AA9: =+X9-SUM(Y9:Z9) -> 0
E10: P7 | F10: 1038 | G10: 19 | H10: 18 | I10: =+F10-SUM(G10:H10) -> 1001 | N10: P20 | O10: 1041 | P10: 19 | Q10: 18 | R10: =+O10-SUM(P10:Q10) -> 1004 | AA10: =+X10-SUM(Y10:Z10) -> 0
E11: P11 | F11: 1037 | G11: 19 | H11: 18 | I11: =+F11-SUM(G11:H11) -> 1000 | N11: P8 | O11: 1043 | P11: 19 | Q11: 18 | R11: =+O11-SUM(P11:Q11) -> 1006 | AA11: =+X11-SUM(Y11:Z11) -> 0
B12: 1 | C12: 2600312302 | E12: P18 | F12: 1042 | G12: 19 | H12: 18 | I12: =+F12-SUM(G12:H12) -> 1005 | K12: 1 | L12: 2611515401 | N12: P17 | O12: 1039 | P12: 19 | Q12: 18 | R12: =+O12-SUM(P12:Q12) -> 1002 | T12: 1 | U12: 2523713501 | AA12: =+X12-SUM(Y12:Z12) -> 0
E13: P5 | F13: 1039 | G13: 19 | H13: 18 | I13: =+F13-SUM(G13:H13) -> 1002 | N13: P16 | O13: 1042 | P13: 19 | Q13: 18 | R13: =+O13-SUM(P13:Q13) -> 1005 | AA13: =+X13-SUM(Y13:Z13) -> 0
E14: P1 | F14: 1041 | G14: 19 | H14: 18 | I14: =+F14-SUM(G14:H14) -> 1004 | N14: P3 | O14: 1039 | P14: 19 | Q14: 18 | R14: =+O14-SUM(P14:Q14) -> 1002 | AA14: =+X14-SUM(Y14:Z14) -> 0
B15: 1 | C15: 2600412301 | E15: P4 | F15: 1040 | G15: 19 | H15: 18 | I15: =+F15-SUM(G15:H15) -> 1003 | K15: 1 | R15: =+O15-SUM(P15:Q15) -> 0 | T15: 1 | U15: 2524313501 | AA15: =+X15-SUM(Y15:Z15) -> 0
E16: P20 | F16: 1041 | G16: 19 | H16: 18 | I16: =+F16-SUM(G16:H16) -> 1004 | R16: =+O16-SUM(P16:Q16) -> 0 | AA16: =+X16-SUM(Y16:Z16) -> 0
E17: P16 | F17: 1037 | G17: 19 | H17: 18 | I17: =+F17-SUM(G17:H17) -> 1000 | R17: =+O17-SUM(P17:Q17) -> 0 | AA17: =+X17-SUM(Y17:Z17) -> 0
B18: 1 | C18: 2600512301 | E18: P8 | F18: 1042 | G18: 19 | H18: 18 | I18: =+F18-SUM(G18:H18) -> 1005 | K18: 1 | R18: =+O18-SUM(P18:Q18) -> 0 | T18: 1 | U18: 2524613501 | AA18: =+X18-SUM(Y18:Z18) -> 0
E19: P2 | F19: 1039 | G19: 19 | H19: 18 | I19: =+F19-SUM(G19:H19) -> 1002 | R19: =+O19-SUM(P19:Q19) -> 0 | AA19: =+X19-SUM(Y19:Z19) -> 0
E20: P7 | F20: 1040 | G20: 19 | H20: 18 | I20: =+F20-SUM(G20:H20) -> 1003 | R20: =+O20-SUM(P20:Q20) -> 0 | AA20: =+X20-SUM(Y20:Z20) -> 0
B21: 1 | C21: 2606212301 | I21: =+F21-SUM(G21:H21) -> 0 | K21: 1 | R21: =+O21-SUM(P21:Q21) -> 0 | T21: 1 | U21: 2526713501 | AA21: =+X21-SUM(Y21:Z21) -> 0
I22: =+F22-SUM(G22:H22) -> 0 | R22: =+O22-SUM(P22:Q22) -> 0 | AA22: =+X22-SUM(Y22:Z22) -> 0
I23: =+F23-SUM(G23:H23) -> 0 | R23: =+O23-SUM(P23:Q23) -> 0 | AA23: =+X23-SUM(Y23:Z23) -> 0
B24: 1 | I24: =+F24-SUM(G24:H24) -> 0 | K24: 1 | R24: =+O24-SUM(P24:Q24) -> 0 | T24: 1 | U24: 2527013501 | AA24: =+X24-SUM(Y24:Z24) -> 0
I25: =+F25-SUM(G25:H25) -> 0 | R25: =+O25-SUM(P25:Q25) -> 0 | AA25: =+X25-SUM(Y25:Z25) -> 0
I26: =+F26-SUM(G26:H26) -> 0 | R26: =+O26-SUM(P26:Q26) -> 0 | AA26: =+X26-SUM(Y26:Z26) -> 0
B27: 1 | I27: =+F27-SUM(G27:H27) -> 0 | K27: 1 | R27: =+O27-SUM(P27:Q27) -> 0 | T27: 1 | U27: 2527413501 | AA27: =+X27-SUM(Y27:Z27) -> 0
I28: =+F28-SUM(G28:H28) -> 0 | R28: =+O28-SUM(P28:Q28) -> 0 | AA28: =+X28-SUM(Y28:Z28) -> 0
I29: =+F29-SUM(G29:H29) -> 0 | R29: =+O29-SUM(P29:Q29) -> 0 | AA29: =+X29-SUM(Y29:Z29) -> 0
B30: 1 | I30: =+F30-SUM(G30:H30) -> 0 | K30: 1 | R30: =+O30-SUM(P30:Q30) -> 0 | T30: 1 | U30: 2528513501 | AA30: =+X30-SUM(Y30:Z30) -> 0
I31: =+F31-SUM(G31:H31) -> 0 | R31: =+O31-SUM(P31:Q31) -> 0 | AA31: =+X31-SUM(Y31:Z31) -> 0
I32: =+F32-SUM(G32:H32) -> 0 | R32: =+O32-SUM(P32:Q32) -> 0 | AA32: =+X32-SUM(Y32:Z32) -> 0
B33: 1 | I33: =+F33-SUM(G33:H33) -> 0 | K33: 1 | R33: =+O33-SUM(P33:Q33) -> 0 | T33: 1 | U33: 2528713501 | AA33: =+X33-SUM(Y33:Z33) -> 0
I34: =+F34-SUM(G34:H34) -> 0 | R34: =+O34-SUM(P34:Q34) -> 0 | AA34: =+X34-SUM(Y34:Z34) -> 0
I35: =+F35-SUM(G35:H35) -> 0 | R35: =+O35-SUM(P35:Q35) -> 0 | AA35: =+X35-SUM(Y35:Z35) -> 0
B36: 1 | I36: =+F36-SUM(G36:H36) -> 0 | K36: 1 | R36: =+O36-SUM(P36:Q36) -> 0 | T36: 1 | U36: 2529113501 | AA36: =+X36-SUM(Y36:Z36) -> 0
I37: =+F37-SUM(G37:H37) -> 0 | R37: =+O37-SUM(P37:Q37) -> 0 | AA37: =+X37-SUM(Y37:Z37) -> 0
I38: =+F38-SUM(G38:H38) -> 0 | R38: =+O38-SUM(P38:Q38) -> 0 | AA38: =+X38-SUM(Y38:Z38) -> 0
B39: 1 | I39: =+F39-SUM(G39:H39) -> 0 | K39: 1 | R39: =+O39-SUM(P39:Q39) -> 0 | T39: 1 | U39: 2529413501 | AA39: =+X39-SUM(Y39:Z39) -> 0
I40: =+F40-SUM(G40:H40) -> 0 | R40: =+O40-SUM(P40:Q40) -> 0 | AA40: =+X40-SUM(Y40:Z40) -> 0
I41: =+F41-SUM(G41:H41) -> 0 | R41: =+O41-SUM(P41:Q41) -> 0 | AA41: =+X41-SUM(Y41:Z41) -> 0
B42: 1 | I42: =+F42-SUM(G42:H42) -> 0 | K42: 1 | R42: =+O42-SUM(P42:Q42) -> 0 | T42: 1 | U42: 2529713501 | AA42: =+X42-SUM(Y42:Z42) -> 0
...

Sheet Feuil1
B2: MASSE | I2: MASSE | R2: BEURRE | AA2: TOURTEAU
B3: Nbre de Lot | C3: N° Lot | D3: Palettes Pesées | I3: Nbre de Lot | J3: N° Lot | L3: Palettes Pesées | R3: Nbre de Lot | S3: N° Lot | U3: Palettes Pesées | AA3: Nbre de Lot | AB3: N° Lot | AD3: Palettes Pesées
B5: 1 | C5: 2421712301 | D5: P1:1039kgs P15:1037kgs P 1:995kgs P16:1037kgs | L5: N° Pal | M5: Poids Brut | N5: Tare Palette | O5: Tare Emballage | P5: Poids Net | U5: N° Pal | V5: Poids Brut | W5: Tare Palette | X5: Tare Emballage | Y5: Poids Net | AD5: N° Pal | AE5: Poids Brut | AF5: Tare Palette | AG5: Tare Emballage | AH5: Poids Net
B6: 1 | C6: 2423812301 | D6: P17:1037kgs P15:1036kgs P5:1038 kgs P19:1035 kgs P10:1039kgs | I6: 1 | J6: 2423812301 | L6: P17 | M6: 1037 | N6: 13 | O6: 2 | P6: =+M6-SUM(N6:O6) -> 1022 | R6: 1 | S6: 2513415401 | U6: P17 | W6: 13 | X6: 2 | Y6: =+V6-SUM(W6:X6) -> -15 | AA6: 1 | AB6: 2434113501 | AD6: P17 | AF6: 13 | AG6: 2 | AH6: =+AE6-SUM(AF6:AG6) -> -15
B7: 1 | C7: 2424012301 | D7: P17:1062kgs P20:1050kgs P 11:1037kgs P14:1059kgs | L7: P15 | M7: 1036 | N7: 13 | O7: 2 | P7: =+M7-SUM(N7:O7) -> 1021 | U7: P15 | W7: 13 | X7: 2 | Y7: =+V7-SUM(W7:X7) -> -15 | AD7: P15 | AF7: 13 | AG7: 2 | AH7: =+AE7-SUM(AF7:AG7) -> -15
B8: 1 | C8: 2424112301 | L8: P5 | M8: 1038 | N8: 13 | O8: 2 | P8: =+M8-SUM(N8:O8) -> 1023 | U8: P5 | W8: 13 | X8: 2 | Y8: =+V8-SUM(W8:X8) -> -15 | AD8: P5 | AF8: 13 | AG8: 2 | AH8: =+AE8-SUM(AF8:AG8) -> -15
B9: 1 | C9: 2424212301
B10: 1 | C10: 2424312301
B11: 1 | C11: 2424412301
B12: 1 | C12: 2424512301
B13: 1 | C13: 2424612301
B14: 1 | C14: 2424712301
B15: 1 | C15: 2424812301
B16: 1 | C16: 2425012301
B17: 1 | C17: 2425112301
B18: 1 | C18: 2425212301
B19: 1 | C19: 2425312301
B20: 1 | C20: 2425512301
... B23: 1 | C23: 2427212301
B24: 1 | C24: 2428512301 | D24: P7:1039kgs P13:1044kgs P 10:1039kgs P3:1041kgs
B25: 1 | C25: 2428612301 | D25: P6:1036kgs P13:1036kgs P7:1040kgs P12:1038kgs
B26: 1 | C26: 2428712301 | D26: P11:1043kgs P20:1042kgs P9:1040kgs P17:1041kgs
B27: 1 | C27: 2428712302 | D27: P5:1048kgs P18:1047kgs P11:1053kgs P2:1048kgs
B28: 1 | C28: 2428912301 | D28: P6:101048kgs P20:1045kgs P3:1046kgs P12:1046kgs
B29: 1 | C29: 2429112301 | D29: P7:1047kgs P3:1047kgs P 2:1047kgs P15:1045kgs
B30: 1 | C30: 2429212301 | D30: P3:1049kgs P12:1049kgs P 17:1040kgs P14:1055kgs
B31: 1 | C31: 2429312301 | D31: P8:1045kgs P20:1046kgs P2:1042kgs P9:1045kgs
B32: 1 | C32: 2429412301
B33: 1 | C33: 2429512301 | D33: P3:1037kgs P16:1039kgs P13:1039kgs P18:1040kgs
B34: 1 | C34: 2429512302 | D34: P1:1042kgs P9:1043kgs P 12:1043kgs P16:1045kgs
B35: 1 | C35: 2429612301 | D35: P19:1044kgs P8:1040kgs P 17:1043kgs P5:1039kgs
B36: 1 | C36: 2429712301 | D36: P4:1046kgs P7:1043kgs P 12:1047kgs P1:1045kgs
B37: 1 | C37: 2429812301 | D37: P3:1039kgs P16:1037kgs P 6:1042kgs P10:1037kgs
B38: 1 | C38: 2429912301 | D38: P9:1038kgs P17:1038kgs P 7:1039kgs P20:1041kgs
B39: 1 | C39: 2429912302 | D39: P1:1041kgs P16:1039kgs P 3:1038kgs P14:1041kgs
B40: 1 | C40: 2430012301 | D40: P18:1041kgs P2:1040kgs P 13:1043kgs P15:1043kgs
B41: 1 | C41: 2430112301 | D41: P7:1037kgs P14:1042kgs P 9:1038kgs P11:1037kgs
B42: 1 | C42: 2430212301 | D42: P2:1038kgs P6:1050kgs P18:1055kgs P12:1052kgs
B43: 1 | C43: 2430312301 | D43: P6:1044kgs P4:1054kgs P11:1058kgs P9:1054kgs
B44: 1 | C44: 2430412301 | D44: P1:1046kgs P3:1044kgs P 7:1040kgs P20:1043kgs
...
